Workbook

Sheet Telecom Customers
A1: customer_id | B1: gender | C1: age | D1: married | E1: number_of_dependents | F1: city | G1: zip_code | H1: latitude | I1: longitude | J1: number_of_referrals | K1: tenure_in_months | L1: offer | M1: phone_service | N1: avg_monthly_long_distance_charges | O1: multiple_lines | P1: internet_service | Q1: internet_type | R1: avg_monthly_gb_download | S1: online_security | T1: online_backup | U1: device_protection_plan | V1: premium_tech_support | W1: streaming_tv | X1: streaming_movies | Y1: streaming_music | Z1: unlimited_data | AA1: contract | AB1: paperless_billing | AC1: payment_method | AD1: monthly_charge | AE1: total_charges | AF1: total_refunds | AG1: total_extra_data_charges | AH1: total_long_distance_charges | AI1: total_revenue | AJ1: customer_status | AK1: churn_category | AL1: churn_reason | AM1: multiple_lines__ | AN1: online_security_
A2: 0002-ORFBO | B2: Female | C2: 37 | D2: Yes | E2: 0 | F2: Frazier Park | G2: 93225 | H2: 34.827662 | I2: -118.99907 | J2: 2 | K2: 9 | L2: 0 | M2: Yes | N2: 42.39 | O2: No | P2: Yes | Q2: Cable | R2: 16 | S2: No | T2: Yes | U2: No | V2: Yes | W2: Yes | X2: No | Y2: No | Z2: Yes | AA2: One Year | AB2: Yes | AC2: Credit Card | AD2: 65.6 | AE2: 593.3 | AF2: 0 | AG2: 0 | AH2: 381.51 | AI2: 974.81 | AJ2: Stayed | AK2: 0 | AL2: 0 | AM2: No | AN2: No
A3: 0003-MKNFE | B3: Male | C3: 46 | D3: No | E3: 0 | F3: Glendale | G3: 91206 | H3: 34.162515 | I3: -118.20387 | J3: 0 | K3: 9 | L3: 0 | M3: Yes | N3: 10.69 | O3: Yes | P3: Yes | Q3: Cable | R3: 10 | S3: No | T3: No | U3: No | V3: No | W3: No | X3: Yes | Y3: Yes | Z3: No | AA3: Month-to-Month | AB3: No | AC3: Credit Card | AD3: -4 | AE3: 542.4 | AF3: 38.33 | AG3: 10 | AH3: 96.21 | AI3: 610.28 | AJ3: Stayed | AK3: 0 | AL3: 0 | AM3: Yes | AN3: No
A4: 0004-TLHLJ | B4: Male | C4: 50 | D4: No | E4: 0 | F4: Costa Mesa | G4: 92627 | H4: 33.645672 | I4: -117.92261 | J4: 0 | K4: 4 | L4: Offer E | M4: Yes | N4: 33.65 | O4: No | P4: Yes | Q4: Fiber Optic | R4: 30 | S4: No | T4: No | U4: Yes | V4: No | W4: No | X4: No | Y4: No | Z4: Yes | AA4: Month-to-Month | AB4: Yes | AC4: Bank Withdrawal | AD4: 73.9 | AE4: 280.85 | AF4: 0 | AG4: 0 | AH4: 134.6 | AI4: 415.45 | AJ4: Churned | AK4: Competitor | AL4: Competitor had better devices | AM4: No | AN4: No
A5: 0011-IGKFF | B5: Male | C5: 78 | D5: Yes | E5: 0 | F5: Martinez | G5: 94553 | H5: 38.014457 | I5: -122.11543 | J5: 1 | K5: 13 | L5: Offer D | M5: Yes | N5: 27.82 | O5: No | P5: Yes | Q5: Fiber Optic | R5: 4 | S5: No | T5: Yes | U5: Yes | V5: No | W5: Yes | X5: Yes | Y5: No | Z5: Yes | AA5: Month-to-Month | AB5: Yes | AC5: Bank Withdrawal | AD5: 98 | AE5: 1237.85 | AF5: 0 | AG5: 0 | AH5: 361.66 | AI5: 1599.51 | AJ5: Churned | AK5: Dissatisfaction | AL5: Product dissatisfaction | AM5: No | AN5: No
A6: 0013-EXCHZ | B6: Female | C6: 75 | D6: Yes | E6: 0 | F6: Camarillo | G6: 93010 | H6: 34.227846 | I6: -119.0799 | J6: 3 | K6: 3 | L6: 0 | M6: Yes | N6: 7.38 | O6: No | P6: Yes | Q6: Fiber Optic | R6: 11 | S6: No | T6: No | U6: No | V6: Yes | W6: Yes | X6: No | Y6: No | Z6: Yes | AA6: Month-to-Month | AB6: Yes | AC6: Credit Card | AD6: 83.9 | AE6: 267.4 | AF6: 0 | AG6: 0 | AH6: 22.14 | AI6: 289.54 | AJ6: Churned | AK6: Dissatisfaction | AL6: Network reliability | AM6: No | AN6: No
A7: 0013-MHZWF | B7: Female | C7: 23 | D7: No | E7: 3 | F7: Midpines | G7: 95345 | H7: 37.581496 | I7: -119.97276 | J7: 0 | K7: 9 | L7: Offer E | M7: Yes | N7: 16.77 | O7: No | P7: Yes | Q7: Cable | R7: 73 | S7: No | T7: No | U7: No | V7: Yes | W7: Yes | X7: Yes | Y7: Yes | Z7: Yes | AA7: Month-to-Month | AB7: Yes | AC7: Credit Card | AD7: 69.4 | AE7: 571.45 | AF7: 0 | AG7: 0 | AH7: 150.93 | AI7: 722.38 | AJ7: Stayed | AK7: 0 | AL7: 0 | AM7: No | AN7: No
A8: 0013-SMEOE | B8: Female | C8: 67 | D8: Yes | E8: 0 | F8: Lompoc | G8: 93437 | H8: 34.757477 | I8: -120.55051 | J8: 1 | K8: 71 | L8: Offer A | M8: Yes | N8: 9.96 | O8: No | P8: Yes | Q8: Fiber Optic | R8: 14 | S8: Yes | T8: Yes | U8: Yes | V8: Yes | W8: Yes | X8: Yes | Y8: Yes | Z8: Yes | AA8: Two Year | AB8: Yes | AC8: Bank Withdrawal | AD8: 109.7 | AE8: 7904.25 | AF8: 0 | AG8: 0 | AH8: 707.16 | AI8: 8611.41 | AJ8: Stayed | AK8: 0 | AL8: 0 | AM8: No | AN8: Yes
A9: 0014-BMAQU | B9: Male | C9: 52 | D9: Yes | E9: 0 | F9: Napa | G9: 94558 | H9: 38.489789 | I9: -122.27011 | J9: 8 | K9: 63 | L9: Offer B | M9: Yes | N9: 12.96 | O9: Yes | P9: Yes | Q9: Fiber Optic | R9: 7 | S9: Yes | T9: No | U9: No | V9: Yes | W9: No | X9: No | Y9: No | Z9: No | AA9: Two Year | AB9: Yes | AC9: Credit Card | AD9: 84.65 | AE9: 5377.8 | AF9: 0 | AG9: 20 | AH9: 816.48 | AI9: 6214.28 | AJ9: Stayed | AK9: 0 | AL9: 0 | AM9: Yes | AN9: Yes
A10: 0015-UOCOJ | B10: Female | C10: 68 | D10: No | E10: 0 | F10: Simi Valley | G10: 93063 | H10: 34.296813 | I10: -118.6857 | J10: 0 | K10: 7 | L10: Offer E | M10: Yes | N10: 10.53 | O10: No | P10: Yes | Q10: DSL | R10: 21 | S10: Yes | T10: No | U10: No | V10: No | W10: No | X10: No | Y10: No | Z10: Yes | AA10: Two Year | AB10: Yes | AC10: Bank Withdrawal | AD10: 48.2 | AE10: 340.35 | AF10: 0 | AG10: 0 | AH10: 73.71 | AI10: 414.06 | AJ10: Stayed | AK10: 0 | AL10: 0 | AM10: No | AN10: Yes
A11: 0016-QLJIS | B11: Female | C11: 43 | D11: Yes | E11: 1 | F11: Sheridan | G11: 95681 | H11: 38.984756 | I11: -121.34507 | J11: 3 | K11: 65 | L11: 0 | M11: Yes | N11: 28.46 | O11: Yes | P11: Yes | Q11: Cable | R11: 14 | S11: Yes | T11: Yes | U11: Yes | V11: Yes | W11: Yes | X11: Yes | Y11: Yes | Z11: Yes | AA11: Two Year | AB11: Yes | AC11: Credit Card | AD11: 90.45 | AE11: 5957.9 | AF11: 0 | AG11: 0 | AH11: 1849.9 | AI11: 7807.8 | AJ11: Stayed | AK11: 0 | AL11: 0 | AM11: Yes | AN11: Yes
A12: 0017-DINOC | B12: Male | C12: 47 | D12: No | E12: 0 | F12: Rancho Santa Fe | G12: 92091 | H12: 32.99356 | I12: -117.20712 | J12: 0 | K12: 54 | L12: 0 | M12: No | N12: 0 | O12: 0 | P12: Yes | Q12: Cable | R12: 10 | S12: Yes | T12: No | U12: No | V12: Yes | W12: Yes | X12: No | Y12: No | Z12: Yes | AA12: Two Year | AB12: No | AC12: Credit Card | AD12: 45.2 | AE12: 2460.55 | AF12: 0 | AG12: 0 | AH12: 0 | AI12: 2460.55 | AJ12: Stayed | AK12: 0 | AL12: 0 | AM12: 0 | AN12: Yes
A13: 0017-IUDMW | B13: Female | C13: 25 | D13: Yes | E13: 2 | F13: Sunnyvale | G13: 94086 | H13: 37.378541 | I13: -122.02046 | J13: 2 | K13: 72 | L13: 0 | M13: Yes | N13: 16.01 | O13: Yes | P13: Yes | Q13: Fiber Optic | R13: 59 | S13: Yes | T13: Yes | U13: Yes | V13: Yes | W13: Yes | X13: Yes | Y13: Yes | Z13: Yes | AA13: Two Year | AB13: Yes | AC13: Credit Card | AD13: 116.8 | AE13: 8456.75 | AF13: 0 | AG13: 0 | AH13: 1152.72 | AI13: 9609.47 | AJ13: Stayed | AK13: 0 | AL13: 0 | AM13: Yes | AN13: Yes
A14: 0018-NYROU | B14: Female | C14: 58 | D14: Yes | E14: 0 | F14: Antelope | G14: 95843 | H14: 38.715498 | I14: -121.36341 | J14: 0 | K14: 5 | L14: 0 | M14: Yes | N14: 18.65 | O14: No | P14: Yes | Q14: Fiber Optic | R14: 10 | S14: No | T14: No | U14: No | V14: No | W14: No | X14: No | Y14: No | Z14: Yes | AA14: Month-to-Month | AB14: Yes | AC14: Bank Withdrawal | AD14: 68.95 | AE14: 351.5 | AF14: 0 | AG14: 0 | AH14: 93.25 | AI14: 444.75 | AJ14: Stayed | AK14: 0 | AL14: 0 | AM14: No | AN14: No
A15: 0019-EFAEP | B15: Female | C15: 32 | D15: No | E15: 0 | F15: La Mesa | G15: 91942 | H15: 32.782501 | I15: -117.01611 | J15: 0 | K15: 72 | L15: Offer A | M15: Yes | N15: 2.25 | O15: Yes | P15: Yes | Q15: Fiber Optic | R15: 16 | S15: Yes | T15: Yes | U15: Yes | V15: No | W15: Yes | X15: No | Y15: No | Z15: Yes | AA15: Two Year | AB15: Yes | AC15: Bank Withdrawal | AD15: 101.3 | AE15: 7261.25 | AF15: 0 | AG15: 0 | AH15: 162 | AI15: 7423.25 | AJ15: Stayed | AK15: 0 | AL15: 0 | AM15: Yes | AN15: Yes
A16: 0019-GFNTW | B16: Female | C16: 39 | D16: No | E16: 0 | F16: Los Olivos | G16: 93441 | H16: 34.70434 | I16: -120.02609 | J16: 0 | K16: 56 | L16: 0 | M16: No | N16: 0 | O16: 0 | P16: Yes | Q16: DSL | R16: 19 | S16: Yes | T16: Yes | U16: Yes | V16: Yes | W16: No | X16: No | Y16: No | Z16: Yes | AA16: Two Year | AB16: No | AC16: Bank Withdrawal | AD16: 45.05 | AE16: 2560.1 | AF16: 0 | AG16: 0 | AH16: 0 | AI16: 2560.1 | AJ16: Stayed | AK16: 0 | AL16: 0 | AM16: 0 | AN16: Yes
A17: 0020-INWCK | B17: Female | C17: 58 | D17: Yes | E17: 2 | F17: Woodlake | G17: 93286 | H17: 36.464635 | I17: -119.09435 | J17: 9 | K17: 71 | L17: Offer A | M17: Yes | N17: 27.26 | O17: Yes | P17: Yes | Q17: Fiber Optic | R17: 12 | S17: No | T17: Yes | U17: Yes | V17: No | W17: No | X17: Yes | Y17: Yes | Z17: Yes | AA17: Two Year | AB17: Yes | AC17: Credit Card | AD17: 95.75 | AE17: 6849.4 | AF17: 0 | AG17: 0 | AH17: 1935.46 | AI17: 8784.86 | AJ17: Stayed | AK17: 0 | AL17: 0 | AM17: Yes | AN17: No
A18: 0020-JDNXP | B18: Female | C18: 52 | D18: Yes | E18: 1 | F18: Point Reyes Station | G18: 94956 | H18: 38.060264 | I18: -122.83065 | J18: 0 | K18: 34 | L18: 0 | M18: No | N18: 0 | O18: 0 | P18: Yes | Q18: DSL | R18: 20 | S18: Yes | T18: No | U18: Yes | V18: Yes | W18: Yes | X18: Yes | Y18: Yes | Z18: Yes | AA18: One Year | AB18: No | AC18: Credit Card | AD18: 61.25 | AE18: 1993.2 | AF18: 0 | AG18: 0 | AH18: 0 | AI18: 1993.2 | AJ18: Stayed | AK18: 0 | AL18: 0 | AM18: 0 | AN18: Yes
A19: 0021-IKXGC | B19: Female | C19: 72 | D19: No | E19: 0 | F19: San Marcos | G19: 92078 | H19: 33.119028 | I19: -117.16604 | J19: 0 | K19: 1 | L19: Offer E | M19: Yes | N19: 7.77 | O19: Yes | P19: Yes | Q19: Fiber Optic | R19: 22 | S19: No | T19: No | U19: No | V19: No | W19: No | X19: No | Y19: No | Z19: Yes | AA19: One Year | AB19: Yes | AC19: Bank Withdrawal | AD19: 72.1 | AE19: 72.1 | AF19: 0 | AG19: 0 | AH19: 7.77 | AI19: 79.87 | AJ19: Joined | AK19: 0 | AL19: 0 | AM19: Yes | AN19: No
A20: 0022-TCJCI | B20: Male | C20: 79 | D20: No | E20: 0 | F20: Daly City | G20: 94015 | H20: 37.680844 | I20: -122.48131 | J20: 0 | K20: 45 | L20: 0 | M20: Yes | N20: 10.67 | O20: No | P20: Yes | Q20: DSL | R20: 17 | S20: Yes | T20: No | U20: Yes | V20: No | W20: No | X20: Yes | Y20: No | Z20: Yes | AA20: One Year | AB20: No | AC20: Credit Card | AD20: 62.7 | AE20: 2791.5 | AF20: 0 | AG20: 0 | AH20: 480.15 | AI20: 3271.65 | AJ20: Churned | AK20: Dissatisfaction | AL20: Limited range of services | AM20: No | AN20: Yes
A21: 0023-HGHWL | B21: Male | C21: 67 | D21: No | E21: 0 | F21: Morgan Hill | G21: 95037 | H21: 37.161544 | I21: -121.64937 | J21: 0 | K21: 1 | L21: 0 | M21: No | N21: 0 | O21: 0 | P21: Yes | Q21: Cable | R21: 9 | S21: No | T21: No | U21: No | V21: No | W21: No | X21: No | Y21: No | Z21: Yes | AA21: Month-to-Month | AB21: Yes | AC21: Bank Withdrawal | AD21: 25.1 | AE21: 25.1 | AF21: 0 | AG21: 0 | AH21: 0 | AI21: 25.1 | AJ21: Churned | AK21: Competitor | AL21: Competitor made better offer | AM21: 0 | AN21: No
A22: 0023-UYUPN | B22: Female | C22: 79 | D22: Yes | E22: 0 | F22: Ahwahnee | G22: 93601 | H22: 37.375816 | I22: -119.73994 | J22: 0 | K22: 50 | L22: 0 | M22: Yes | N22: 31.43 | O22: Yes | P22: No | Q22: 0 | R22: 0 | S22: 0 | T22: 0 | U22: 0 | V22: 0 | W22: 0 | X22: 0 | Y22: 0 | Z22: 0 | AA22: One Year | AB22: No | AC22: Bank Withdrawal | AD22: 25.2 | AE22: 1306.3 | AF22: 0 | AG22: 0 | AH22: 1571.5 | AI22: 2877.8 | AJ22: Stayed | AK22: 0 | AL22: 0 | AM22: Yes | AN22: 0
A23: 0023-XUOPT | B23: Female | C23: 26 | D23: Yes | E23: 0 | F23: Carnelian Bay | G23: 96140 | H23: 39.227434 | I23: -120.09181 | J23: 1 | K23: 13 | L23: 0 | M23: Yes | N23: 43.56 | O23: Yes | P23: Yes | Q23: Fiber Optic | R23: 52 | S23: No | T23: Yes | U23: Yes | V23: No | W23: Yes | X23: No | Y23: No | Z23: Yes | AA23: Month-to-Month | AB23: No | AC23: Bank Withdrawal | AD23: 94.1 | AE23: 1215.6 | AF23: 0 | AG23: 0 | AH23: 566.28 | AI23: 1781.88 | AJ23: Churned | AK23: Other | AL23: Don't know | AM23: Yes | AN23: No
A24: 0027-KWYKW | B24: Female | C24: 30 | D24: Yes | E24: 2 | F24: Alpaugh | G24: 93201 | H24: 35.869626 | I24: -119.49877 | J24: 1 | K24: 23 | L24: Offer D | M24: Yes | N24: 34.91 | O24: Yes | P24: Yes | Q24: Fiber Optic | R24: 30 | S24: No | T24: No | U24: No | V24: No | W24: Yes | X24: No | Y24: No | Z24: Yes | AA24: Month-to-Month | AB24: Yes | AC24: Bank Withdrawal | AD24: 83.75 | AE24: 1849.95 | AF24: 0 | AG24: 0 | AH24: 802.93 | AI24: 2652.88 | AJ24: Stayed | AK24: 0 | AL24: 0 | AM24: Yes | AN24: No
A25: 0030-FNXPP | B25: Female | C25: 22 | D25: No | E25: 0 | F25: Keeler | G25: 93530 | H25: 36.560498 | I25: -117.96246 | J25: 0 | K25: 3 | L25: 0 | M25: Yes | N25: 3.12 | O25: No | P25: No | Q25: 0 | R25: 0 | S25: 0 | T25: 0 | U25: 0 | V25: 0 | W25: 0 | X25: 0 | Y25: 0 | Z25: 0 | AA25: Month-to-Month | AB25: No | AC25: Credit Card | AD25: 19.85 | AE25: 57.2 | AF25: 0 | AG25: 0 | AH25: 9.36 | AI25: 66.56 | AJ25: Joined | AK25: 0 | AL25: 0 | AM25: No | AN25: 0
A26: 0031-PVLZI | B26: Female | C26: 34 | D26: Yes | E26: 0 | F26: Korbel | G26: 95550 | H26: 40.7666 | I26: -123.80458 | J26: 0 | K26: 4 | L26: Offer E | M26: Yes | N26: 12.43 | O26: No | P26: No | Q26: 0 | R26: 0 | S26: 0 | T26: 0 | U26: 0 | V26: 0 | W26: 0 | X26: 0 | Y26: 0 | Z26: 0 | AA26: Month-to-Month | AB26: No | AC26: Credit Card | AD26: 20.35 | AE26: 76.35 | AF26: 0 | AG26: 0 | AH26: 49.72 | AI26: 126.07 | AJ26: Churned | AK26: Price | AL26: Long distance charges | AM26: No | AN26: 0
A27: 0032-PGELS | B27: Female | C27: 37 | D27: Yes | E27: 1 | F27: Palomar Mountain | G27: 92060 | H27: 33.309852 | I27: -116.82309 | J27: 1 | K27: 1 | L27: 0 | M27: No | N27: 0 | O27: 0 | P27: Yes | Q27: DSL | R27: 19 | S27: Yes | T27: No | U27: No | V27: No | W27: No | X27: No | Y27: No | Z27: Yes | AA27: Month-to-Month | AB27: No | AC27: Bank Withdrawal | AD27: 30.5 | AE27: 30.5 | AF27: 0 | AG27: 0 | AH27: 0 | AI27: 30.5 | AJ27: Churned | AK27: Attitude | AL27: Attitude of service provider | AM27: 0 | AN27: Yes
A28: 0036-IHMOT | B28: Female | C28: 37 | D28: Yes | E28: 3 | F28: Parlier | G28: 93648 | H28: 36.622237 | I28: -119.52113 | J28: 10 | K28: 55 | L28: 0 | M28: Yes | N28: 35.04 | O28: No | P28: Yes | Q28: Fiber Optic | R28: 57 | S28: No | T28: Yes | U28: Yes | V28: Yes | W28: Yes | X28: Yes | Y28: Yes | Z28: No | AA28: One Year | AB28: Yes | AC28: Bank Withdrawal | AD28: 103.7 | AE28: 5656.75 | AF28: 0 | AG28: 20 | AH28: 1927.2 | AI28: 7603.95 | AJ28: Stayed | AK28: 0 | AL28: 0 | AM28: No | AN28: No
A29: 0040-HALCW | B29: Male | C29: 42 | D29: Yes | E29: 3 | F29: Modesto | G29: 95358 | H29: 37.612612 | I29: -121.10857 | J29: 3 | K29: 54 | L29: 0 | M29: Yes | N29: 19.7 | O29: No | P29: No | Q29: 0 | R29: 0 | S29: 0 | T29: 0 | U29: 0 | V29: 0 | W29: 0 | X29: 0 | Y29: 0 | Z29: 0 | AA29: Two Year | AB29: No | AC29: Credit Card | AD29: 20.4 | AE29: 1090.6 | AF29: 0 | AG29: 0 | AH29: 1063.8 | AI29: 2154.4 | AJ29: Stayed | AK29: 0 | AL29: 0 | AM29: No | AN29: 0
A30: 0042-JVWOJ | B30: Male | C30: 64 | D30: No | E30: 0 | F30: Glen Ellen | G30: 95442 | H30: 38.368744 | I30: -122.52264 | J30: 0 | K30: 26 | L30: Offer C | M30: Yes | N30: 37.7 | O30: No | P30: No | Q30: 0 | R30: 0 | S30: 0 | T30: 0 | U30: 0 | V30: 0 | W30: 0 | X30: 0 | Y30: 0 | Z30: 0 | AA30: One Year | AB30: Yes | AC30: Bank Withdrawal | AD30: 19.6 | AE30: 471.85 | AF30: 21.25 | AG30: 0 | AH30: 980.2 | AI30: 1430.8 | AJ30: Stayed | AK30: 0 | AL30: 0 | AM30: No | AN30: 0
A31: 0042-RLHYP | B31: Female | C31: 47 | D31: Yes | E31: 3 | F31: Eureka | G31: 95503 | H31: 40.737431 | I31: -124.1089 | J31: 5 | K31: 69 | L31: 0 | M31: Yes | N31: 38.39 | O31: No | P31: No | Q31: 0 | R31: 0 | S31: 0 | T31: 0 | U31: 0 | V31: 0 | W31: 0 | X31: 0 | Y31: 0 | Z31: 0 | AA31: Two Year | AB31: No | AC31: Bank Withdrawal | AD31: 19.7 | AE31: 1396.9 | AF31: 0 | AG31: 0 | AH31: 2648.91 | AI31: 4045.81 | AJ31: Stayed | AK31: 0 | AL31: 0 | AM31: No | AN31: 0
A32: 0048-LUMLS | B32: Male | C32: 23 | D32: Yes | E32: 3 | F32: Moss Beach | G32: 94038 | H32: 37.515556 | I32: -122.50231 | J32: 1 | K32: 37 | L32: Offer C | M32: Yes | N32: 43.01 | O32: No | P32: Yes | Q32: Fiber Optic | R32: 51 | S32: No | T32: No | U32: No | V32: No | W32: Yes | X32: Yes | Y32: Yes | Z32: Yes | AA32: One Year | AB32: No | AC32: Credit Card | AD32: 91.2 | AE32: 3247.55 | AF32: 0 | AG32: 0 | AH32: 1591.37 | AI32: 4838.92 | AJ32: Stayed | AK32: 0 | AL32: 0 | AM32: No | AN32: No
A33: 0048-PIHNL | B33: Female | C33: 48 | D33: Yes | E33: 0 | F33: Los Angeles | G33: 90058 | H33: 34.001617 | I33: -118.22227 | J33: 5 | K33: 49 | L33: Offer B | M33: Yes | N33: 49.58 | O33: No | P33: No | Q33: 0 | R33: 0 | S33: 0 | T33: 0 | U33: 0 | V33: 0 | W33: 0 | X33: 0 | Y33: 0 | Z33: 0 | AA33: One Year | AB33: No | AC33: Bank Withdrawal | AD33: 20.45 | AE33: 900.9 | AF33: 0 | AG33: 0 | AH33: 2429.42 | AI33: 3330.32 | AJ33: Stayed | AK33: 0 | AL33: 0 | AM33: No | AN33: 0
A34: 0052-DCKON | B34: Male | C34: 28 | D34: Yes | E34: 0 | F34: Los Angeles | G34: 90063 | H34: 34.044271 | I34: -118.18524 | J34: 9 | K34: 66 | L34: 0 | M34: Yes | N34: 43.77 | O34: Yes | P34: Yes | Q34: Fiber Optic | R34: 41 | S34: Yes | T34: Yes | U34: Yes | V34: Yes | W34: Yes | X34: Yes | Y34: Yes | Z34: Yes | AA34: One Year | AB34: No | AC34: Bank Withdrawal | AD34: -2 | AE34: 7942.15 | AF34: 0 | AG34: 0 | AH34: 2888.82 | AI34: 10830.97 | AJ34: Stayed | AK34: 0 | AL34: 0 | AM34: Yes | AN34: Yes
A35: 0052-YNYOT | B35: Female | C35: 28 | D35: No | E35: 0 | F35: Calexico | G35: 92231 | H35: 32.690654 | I35: -115.43122 | J35: 0 | K35: 67 | L35: 0 | M35: Yes | N35: 23.12 | O35: No | P35: No | Q35: 0 | R35: 0 | S35: 0 | T35: 0 | U35: 0 | V35: 0 | W35: 0 | X35: 0 | Y35: 0 | Z35: 0 | AA35: One Year | AB35: No | AC35: Bank Withdrawal | AD35: 20.55 | AE35: 1343.4 | AF35: 30.53 | AG35: 0 | AH35: 1549.04 | AI35: 2861.91 | AJ35: Stayed | AK35: 0 | AL35: 0 | AM35: No | AN35: 0
A36: 0056-EPFBG | B36: Male | C36: 33 | D36: Yes | E36: 1 | F36: Redding | G36: 96003 | H36: 40.677649 | I36: -122.29467 | J36: 4 | K36: 20 | L36: 0 | M36: No | N36: 0 | O36: 0 | P36: Yes | Q36: Cable | R36: 22 | S36: Yes | T36: No | U36: Yes | V36: Yes | W36: No | X36: No | Y36: No | Z36: Yes | AA36: Two Year | AB36: Yes | AC36: Credit Card | AD36: 39.4 | AE36: 825.4 | AF36: 0 | AG36: 0 | AH36: 0 | AI36: 825.4 | AJ36: Stayed | AK36: 0 | AL36: 0 | AM36: 0 | AN36: Yes
A37: 0057-QBUQH | B37: Female | C37: 31 | D37: No | E37: 3 | F37: San Martin | G37: 95046 | H37: 37.084697 | I37: -121.60642 | J37: 0 | K37: 43 | L37: 0 | M37: Yes | N37: 30.64 | O37: Yes | P37: No | Q37: 0 | R37: 0 | S37: 0 | T37: 0 | U37: 0 | V37: 0 | W37: 0 | X37: 0 | Y37: 0 | Z37: 0 | AA37: Two Year | AB37: Yes | AC37: Bank Withdrawal | AD37: 25.1 | AE37: 1070.15 | AF37: 0 | AG37: 0 | AH37: 1317.52 | AI37: 2387.67 | AJ37: Stayed | AK37: 0 | AL37: 0 | AM37: Yes | AN37: 0
A38: 0058-EVZWM | B38: Female | C38: 37 | D38: Yes | E38: 0 | F38: Stockton | G38: 95209 | H38: 38.044523 | I38: -121.34805 | J38: 2 | K38: 55 | L38: Offer B | M38: Yes | N38: 5.08 | O38: Yes | P38: Yes | Q38: Fiber Optic | R38: 9 | S38: Yes | T38: No | U38: No | V38: No | W38: Yes | X38: No | Y38: No | Z38: Yes | AA38: Month-to-Month | AB38: Yes | AC38: Bank Withdrawal | AD38: 89.8 | AE38: 4959.6 | AF38: 0 | AG38: 0 | AH38: 279.4 | AI38: 5239 | AJ38: Stayed | AK38: 0 | AL38: 0 | AM38: Yes | AN38: Yes
A39: 0060-FUALY | B39: Female | C39: 60 | D39: Yes | E39: 0 | F39: Los Angeles | G39: 90003 | H39: 33.964131 | I39: -118.27278 | J39: 4 | K39: 59 | L39: Offer B | M39: Yes | N39: 16.39 | O39: Yes | P39: Yes | Q39: Fiber Optic | R39: 14 | S39: Yes | T39: Yes | U39: No | V39: No | W39: Yes | X39: No | Y39: No | Z39: Yes | AA39: Month-to-Month | AB39: Yes | AC39: Bank Withdrawal | AD39: 94.75 | AE39: 5597.65 | AF39: 0 | AG39: 0 | AH39: 967.01 | AI39: 6564.66 | AJ39: Stayed | AK39: 0 | AL39: 0 | AM39: Yes | AN39: Yes
A40: 0064-SUDOG | B40: Female | C40: 48 | D40: Yes | E40: 3 | F40: Huntington Park | G40: 90255 | H40: 33.97803 | I40: -118.21714 | J40: 3 | K40: 12 | L40: 0 | M40: Yes | N40: 19.28 | O40: No | P40: No | Q40: 0 | R40: 0 | S40: 0 | T40: 0 | U40: 0 | V40: 0 | W40: 0 | X40: 0 | Y40: 0 | Z40: 0 | AA40: Two Year | AB40: No | AC40: Bank Withdrawal | AD40: 20.3 | AE40: 224.5 | AF40: 0 | AG40: 0 | AH40: 231.36 | AI40: 455.86 | AJ40: Stayed | AK40: 0 | AL40: 0 | AM40: No | AN40: 0
...

Sheet Analysis
D2: Telecom Churn Customers Analysis
A8: Total Customers | C8: =COUNTA(Table1[customer_id]) -> 7043 | E8: Churned Customers | G8: =COUNTIF(Table1[[#All],[customer_status]],"Churned") -> 1869 | I8: Churn Rate | K8: =G8/C8 -> 0.26536987
A11: Stayed Customers | C11: =COUNTIF(Table1[[#All],[customer_status]],"Stayed") -> 4720 | E11: Joined Customers | G11: =COUNTIF(Table1[[#All],[customer_status]],"Joined") -> 454 | I11: Total Revenue | K11: =SUM(Table1[[#All],[total_charges]]) -> 16060725
A15: 1. Contract Performance
A16: Contract | B16: Customers | C16: Churned | D16: Churn Rate | F16: Variance
A17: Month-to-Month | B17: =COUNTIF(Table1[[#All],[contract]],Analysis!A17) -> 3610 | C17: =COUNTIFS(Table1[[#All],[contract]],Analysis!A17,Table1[[#All],[customer_status]],"Churned") -> 1655 | D17: =IFERROR(C17/B17,0) -> 0.45844875
A18: One Year | B18: =COUNTIF(Table1[[#All],[contract]],Analysis!A18) -> 1550 | C18: =COUNTIFS(Table1[[#All],[contract]],Analysis!A18,Table1[[#All],[customer_status]],"Churned") -> 166 | D18: =IFERROR(C18/B18,0) -> 0.10709677
A19: Two Year | B19: =COUNTIF(Table1[[#All],[contract]],Analysis!A19) -> 1883 | C19: =COUNTIFS(Table1[[#All],[contract]],Analysis!A19,Table1[[#All],[customer_status]],"Churned") -> 48 | D19: =IFERROR(C19/B19,0) -> 0.025491237
A22: 2. Internet Type Churn Analysis
A23: Internet Type | B23: Customers | C23: Churned | D23: Churn Rate | E23: Avg Monthly Charge | F23: Total Revenue
A24: 0 | B24: =COUNTIF(Table1[[#All],[internet_type]],Analysis!A24) -> 1526 | C24: =COUNTIFS(Table1[[#All],[internet_type]],Analysis!A24,Table1[[#All],[customer_status]],"Churned") -> 113 | D24: =C24/B24 -> 0.074049803 | E24: =AVERAGEIF(Table1[internet_type],Analysis!A24,Table1[monthly_charge]) -> 20.613925 | F24: =SUMIF(Table1[[#All],[internet_type]],Analysis!A24,Table1[[#All],[total_revenue]]) -> 2185293.5
A25: Cable | B25: =COUNTIF(Table1[[#All],[internet_type]],Analysis!A25) -> 830 | C25: =COUNTIFS(Table1[[#All],[internet_type]],Analysis!A25,Table1[[#All],[customer_status]],"Churned") -> 213 | D25: =C25/B25 -> 0.25662651 | E25: =AVERAGEIF(Table1[internet_type],Analysis!A25,Table1[monthly_charge]) -> 59.355361 | F25: =SUMIF(Table1[[#All],[internet_type]],Analysis!A25,Table1[[#All],[total_revenue]]) -> 2228474.2
A26: DSL | B26: =COUNTIF(Table1[[#All],[internet_type]],Analysis!A26) -> 1652 | C26: =COUNTIFS(Table1[[#All],[internet_type]],Analysis!A26,Table1[[#All],[customer_status]],"Churned") -> 307 | D26: =C26/B26 -> 0.18583535 | E26: =AVERAGEIF(Table1[internet_type],Analysis!A26,Table1[monthly_charge]) -> 56.792494 | F26: =SUMIF(Table1[[#All],[internet_type]],Analysis!A26,Table1[[#All],[total_revenue]]) -> 4549289.6
A27: Fiber Optic | B27: =COUNTIF(Table1[[#All],[internet_type]],Analysis!A27) -> 3035 | C27: =COUNTIFS(Table1[[#All],[internet_type]],Analysis!A27,Table1[[#All],[customer_status]],"Churned") -> 1236 | D27: =C27/B27 -> 0.40724876 | E27: =AVERAGEIF(Table1[internet_type],Analysis!A27,Table1[monthly_charge]) -> 90.070692 | F27: =SUMIF(Table1[[#All],[internet_type]],Analysis!A27,Table1[[#All],[total_revenue]]) -> 12408074
A30: 3. Tenure Group Analysis
A31: Tenure Group | B31: Customers | C31: Churned | D31: Churn Rate
A32: 0-12 Months | B32: =COUNTIFS(Table1[tenure_in_months],">=0",Table1[tenure_in_months],"<=12") -> 2186 | C32: =COUNTIFS(Table1[tenure_in_months],">=0",Table1[tenure_in_months],"<=12",Table1[customer_status],"Churned") -> 1037 | D32: =C32/B32 -> 0.47438243
A33: 13-24 Months | B33: =COUNTIFS(Table1[[#All],[tenure_in_months]],">=12",Table1[[#All],[tenure_in_months]],"<=24") -> 1141 | C33: =COUNTIFS(Table1[tenure_in_months],">=12",Table1[tenure_in_months],"<=24",Table1[customer_status],"Churned") -> 332 | D33: =C33/B33 -> 0.29097283
A34: 25-48 Months | B34: =COUNTIFS(Table1[[#All],[tenure_in_months]],">=24",Table1[[#All],[tenure_in_months]],"<=48") -> 1688 | C34: =COUNTIFS(Table1[tenure_in_months],">=24",Table1[tenure_in_months],"<=48",Table1[customer_status],"Churned") -> 348 | D34: =C34/B34 -> 0.20616114
A35: 49-72 Months | B35: =COUNTIFS(Table1[[#All],[tenure_in_months]],">=48",Table1[[#All],[tenure_in_months]],"<=72") -> 2303 | C35: =COUNTIFS(Table1[tenure_in_months],">=48",Table1[tenure_in_months],"<=72",Table1[customer_status],"Churned") -> 222 | D35: =C35/B35 -> 0.096396005
A36: 72+ Months | B36: =COUNTIF(Table1[[#All],[tenure_in_months]],">=72") -> 362 | C36: =COUNTIFS(Table1[tenure_in_months],">=72",Table1[customer_status],"Churned") -> 6 | D36: =C36/B36 -> 0.016574586
A39: 4. Churn Reason Analysis
A40: Churn Reason | B40: Churned Customers | C40: Revenue Lost
A41: Attitude of service provider | B41: =COUNTIFS(Table1[churn_reason],Analysis!A41,Table1[customer_status],"Churned") -> 94 | C41: =SUMIFS(Table1[total_revenue],Table1[churn_reason],Analysis!A41,Table1[customer_status],"Churned") -> 174858.74
A42: Attitude of support person | B42: =COUNTIFS(Table1[churn_reason],Analysis!A42,Table1[customer_status],"Churned") -> 220 | C42: =SUMIFS(Table1[total_revenue],Table1[churn_reason],Analysis!A42,Table1[customer_status],"Churned") -> 404695.39
A43: Competitor had better devices | B43: =COUNTIFS(Table1[churn_reason],Analysis!A43,Table1[customer_status],"Churned") -> 313 | C43: =SUMIFS(Table1[total_revenue],Table1[churn_reason],Analysis!A43,Table1[customer_status],"Churned") -> 579877.05
A44: Competitor made better offer | B44: =COUNTIFS(Table1[churn_reason],Analysis!A44,Table1[customer_status],"Churned") -> 311 | C44: =SUMIFS(Table1[total_revenue],Table1[churn_reason],Analysis!A44,Table1[customer_status],"Churned") -> 582822.2
A45: Competitor offered higher download speeds | B45: =COUNTIFS(Table1[churn_reason],Analysis!A45,Table1[customer_status],"Churned") -> 100 | C45: =SUMIFS(Table1[total_revenue],Table1[churn_reason],Analysis!A45,Table1[customer_status],"Churned") -> 234145.69
A46: Competitor offered more data | B46: =COUNTIFS(Table1[churn_reason],Analysis!A46,Table1[customer_status],"Churned") -> 117 | C46: =SUMIFS(Table1[total_revenue],Table1[churn_reason],Analysis!A46,Table1[customer_status],"Churned") -> 297568.21
A47: Deceased | B47: =COUNTIFS(Table1[churn_reason],Analysis!A47,Table1[customer_status],"Churned") -> 6 | C47: =SUMIFS(Table1[total_revenue],Table1[churn_reason],Analysis!A47,Table1[customer_status],"Churned") -> 4172.83
A48: Don't know | B48: =COUNTIFS(Table1[churn_reason],Analysis!A48,Table1[customer_status],"Churned") -> 130 | C48: =SUMIFS(Table1[total_revenue],Table1[churn_reason],Analysis!A48,Table1[customer_status],"Churned") -> 256403.35
A49: Extra data charges | B49: =COUNTIFS(Table1[churn_reason],Analysis!A49,Table1[customer_status],"Churned") -> 39 | C49: =SUMIFS(Table1[total_revenue],Table1[churn_reason],Analysis!A49,Table1[customer_status],"Churned") -> 104152.72
A50: Lack of affordable download/upload speed | B50: =COUNTIFS(Table1[churn_reason],Analysis!A50,Table1[customer_status],"Churned") -> 30 | C50: =SUMIFS(Table1[total_revenue],Table1[churn_reason],Analysis!A50,Table1[customer_status],"Churned") -> 66772.76
A51: Lack of self-service on Website | B51: =COUNTIFS(Table1[churn_reason],Analysis!A51,Table1[customer_status],"Churned") -> 29 | C51: =SUMIFS(Table1[total_revenue],Table1[churn_reason],Analysis!A51,Table1[customer_status],"Churned") -> 36788.15
A52: Limited range of services | B52: =COUNTIFS(Table1[churn_reason],Analysis!A52,Table1[customer_status],"Churned") -> 37 | C52: =SUMIFS(Table1[total_revenue],Table1[churn_reason],Analysis!A52,Table1[customer_status],"Churned") -> 47254.43
... A60: Service dissatisfaction | B60: =COUNTIFS(Table1[churn_reason],Analysis!A60,Table1[customer_status],"Churned") -> 63 | C60: =SUMIFS(Table1[total_revenue],Table1[churn_reason],Analysis!A60,Table1[customer_status],"Churned") -> 122914.14
